Workbook

Sheet Data Penerima
A1: No | B1: Sumber Dana | C1: Jenis Sumber Dana | D1: Kecamatan | E1: Desa/Kelurahan | F1: Poktan/Brigade Pangan | G1: Nama Ketua | H1: NIK | I1: No Telp/HP | J1: Jlh Anggota (Org) | K1: Luas Lahan (Ha) | L1: Volume Benih (Kg) | M1: Varietas yang diusulkan | N1: Jadwal Tanam | O1: Titik Koordinat Lintang | P1: Titik Koordinat Bujur | Q1: Terdaftar di SIMLUHTAN (Ya/Tidak) | R1: Status (Salur/Belum Salur)
A2: =IF(D2="","",ROW()-1) -> 1 | B2: APBD Kabupaten | C2: Induk | D2: Saipar Dolok Hole | E2: Parau Sorat Sitabo-tabo | F2: Sahata | G2: Amrianto Sihombing | H2: 1404041004900004 | I2: 085376713545 | J2: 20 | K2: =L2/15 -> 3.3333333 | L2: 50 | M2: BISI 18 | N2: Juni | Q2: Ya | R2: Salur
A3: =IF(D3="","",ROW()-1) -> 2 | B3: APBD Kabupaten | C3: Induk | D3: Sipirok | E3: Simaninggir | F3: Sahata | G3: Rahman Saleh Harahap | H3: 1203042711840002 | I3: 081265490402 | J3: 23 | K3: 4.6 | L3: 70 | M3: BISI 18 | N3: Juni | Q3: Ya | R3: Salur
A4: =IF(D4="","",ROW()-1) -> 3 | B4: APBD Kabupaten | C4: Induk | D4: Sipirok | E4: Pasar Sipirok | F4: Sepakat | G4: Sakti Raja | H4: 1203042908650001 | I4: 082162531546 | J4: 15 | K4: 7 | L4: =K4*15 -> 105 | M4: BISI 18 | N4: Juni | Q4: Ya | R4: Salur
A5: =IF(D5="","",ROW()-1) -> 4 | B5: APBD Kabupaten | C5: Induk | D5: Arse | E5: Nanggarjati Hutapadang | F5: Saroha | G5: Sugianto Sitompul | H5: 1203142701800001 | I5: 085261721119 | J5: 20 | K5: 10 | L5: =K5*15 -> 150 | M5: BISI 18 | N5: Juni | Q5: Ya | R5: Salur
A6: =IF(D6="","",ROW()-1) -> 5 | B6: APBD Kabupaten | C6: Induk | D6: Arse | E6: Nanggarjati | F6: Pardamean | G6: Nurhotma Delina | H6: 1203145612830001 | I6: 085358162445 | J6: 25 | K6: 10 | L6: =K6*15 -> 150 | M6: BISI 18 | N6: Juni | Q6: Ya | R6: Salur
A7: =IF(D7="","",ROW()-1) -> 6 | B7: APBD Kabupaten | C7: Induk | D7: Sipirok | E7: Panaungan | F7: Berkah | G7: Parmaidi | H7: 1203040307840006 | J7: 20 | K7: =L7/15 -> 3.3333333 | L7: 50 | M7: BISI 18 | N7: Juni | Q7: Ya | R7: Salur
A8: =IF(D8="","",ROW()-1) -> 7 | B8: APBD Kabupaten | C8: DBH | D8: Batang Angkola | E8: Huta Padang | F8: Saroha | G8: Vensentius Siringo Ringo | H8: 1203073010590001 | I8: 081376116229 | J8: 20 | K8: 5 | L8: 75 | M8: BISI 18 | N8: Oktober | Q8: Ya | R8: Salur
A9: =IF(D9="","",ROW()-1) -> 8 | B9: APBD Kabupaten | C9: DBH | D9: Batang Angkola | E9: Sorik | F9: Sinondang Bulan | G9: Amin Hijari Matondang | H9: 1203072808730003 | I9: 08216491526 | J9: 42 | K9: 4 | L9: 60 | M9: BISI 18 | N9: Oktober | Q9: Ya | R9: Salur
A10: =IF(D10="","",ROW()-1) -> 9 | B10: APBD Kabupaten | C10: DBH | D10: Sayur Matinggi | E10: Mondang | F10: Harapan | G10: Bukhori Muslim | H10: 1203210606690001 | I10: 082174683832 | J10: 24 | K10: 3 | L10: 45 | M10: BISI 18 | N10: Oktober | Q10: Ya | R10: Salur
A11: =IF(D11="","",ROW()-1) -> 10 | B11: APBD Kabupaten | C11: DBH | D11: Sayur Matinggi | E11: Sialang | F11: Serasi Jaya | G11: Ratna Wati Daulay | H11: 1203215005680003 | I11: 081360455718 | J11: 30 | K11: 4 | L11: 60 | M11: BISI 18 | N11: Oktober | Q11: Ya | R11: Salur
A12: =IF(D12="","",ROW()-1) -> 11 | B12: APBD Kabupaten | C12: DBH | D12: Sayur Matinggi | E12: Bange | F12: Mawar | G12: Ardi Harahap | H12: 1203213012650002 | I12: 085372284359 | J12: 23 | K12: 4 | L12: 60 | M12: BISI 18 | N12: Oktober | Q12: Ya | R12: Salur
A13: =IF(D13="","",ROW()-1) -> 12 | B13: APBD Kabupaten | C13: DBH | D13: Tano Tombangan Angkola | E13: Ingul Jae | F13: Sahabat | G13: Soritua Sinamo | H13: 1203210307640004 | I13: 081370063594 | J13: 20 | K13: 5 | L13: 75 | M13: BISI 18 | N13: Oktober | Q13: Ya | R13: Salur
A14: =IF(D14="","",ROW()-1) -> 13 | B14: APBD Kabupaten | C14: DBH | D14: Tano Tombangan Angkola | E14: Sisoma | F14: Usaha Tani | G14: Sabar Manaon Ritonga | H14: 120321160972001 | I14: 082167411421 | J14: 28 | K14: 5 | L14: 75 | M14: BISI 18 | N14: Oktober | Q14: Ya | R14: Salur
A15: =IF(D15="","",ROW()-1) -> 14 | B15: APBD Kabupaten | C15: DBH | D15: Angkola Barat | E15: Pasar Sitinjak | F15: Salak Berduri | G15: Hermin Anata Harahap | H15: 1203010905860003 | I15: 085361608196 | J15: 30 | K15: 4 | L15: 60 | M15: BISI 18 | N15: Oktober | Q15: Ya | R15: Salur
A16: =IF(D16="","",ROW()-1) -> 15 | B16: APBD Kabupaten | C16: DBH | D16: Marancar | E16: Sugi | F16: Silotik | G16: Emmida | H16: 1203206609870001 | I16: 081376061863 | J16: 25 | K16: 4 | L16: 60 | M16: BISI 18 | N16: Oktober | Q16: Ya | R16: Salur
A17: =IF(D17="","",ROW()-1) -> 16 | B17: APBD Kabupaten | C17: DBH | D17: Saipar Dolok Hole | E17: Ulumamis | F17: Pardomuan | G17: Pamohonan Rambe | H17: 127705018720003 | I17: 081273515558 | J17: 34 | K17: 12 | L17: 180 | M17: BISI 18 | N17: Oktober | Q17: Ya | R17: Salur
A18: =IF(D18="","",ROW()-1) -> 17 | B18: APBD Kabupaten | C18: DBH | D18: Arse | E18: Arse Nauli | F18: Anggrek | G18: Juliana Panggabean | H18: 1203147108690001 | I18: 082277760928 | J18: 15 | K18: 3 | L18: 45 | M18: BISI 18 | N18: Oktober | Q18: Ya | R18: Salur
A19: =IF(D19="","",ROW()-1) -> 18 | B19: APBD Kabupaten | C19: DBH | D19: Arse | E19: Nanggar Jati | F19: Suka Maju | G19: Maslan Lubis | H19: 1203144508600001 | I19: 085358162445 | J19: 15 | K19: 4 | L19: 60 | M19: BISI 18 | N19: Oktober | Q19: Ya | R19: Salur
... A24: =IF(D24="","",ROW()-1) -> 23 | B24: APBD Provinsi | C24: Induk | D24: Sipirok | E24: Baringin | F24: Sepakat | G24: Maraden Siregar | H24: 1203041812730002 | I24: 083896006209 | J24: 18 | K24: 5 | L24: 75 | M24: Pioneer 32 | N24: Mei | Q24: Ya | R24: Salur
A25: =IF(D25="","",ROW()-1) -> 24 | B25: APBD Provinsi | C25: Induk | D25: Sipirok | E25: Baringin | F25: Mardomu Tahi | G25: Rismadewi Siregar | J25: 20 | K25: 5 | L25: 75 | M25: Pioneer 32 | N25: Mei | Q25: Ya | R25: Salur
A26: =IF(D26="","",ROW()-1) -> 25 | B26: APBD Provinsi | C26: Induk | D26: Sipirok | E26: Baringin | F26: Tona Marsiurupan | G26: Marson Siregar | J26: 22 | K26: 5 | L26: 75 | M26: Pioneer 32 | N26: Mei | Q26: Ya | R26: Salur
A27: =IF(D27="","",ROW()-1) -> 26 | B27: APBD Provinsi | C27: Induk | D27: Sipirok | E27: Baringin | F27: Tunas Harapan | G27: Ahmad Muhajir Siregar | J27: 20 | K27: 5 | L27: 75 | M27: Pioneer 32 | N27: Mei | Q27: Ya | R27: Salur
A28: =IF(D28="","",ROW()-1) -> 27 | B28: APBD Provinsi | C28: Induk | D28: Sipirok | E28: Baringin | F28: Cinta Damai | G28: Labora Sohombing | H28: 1203214202870011 | I28: 082299807751 | J28: 15 | K28: 5 | L28: 75 | M28: Pioneer 32 | N28: Mei | Q28: Ya | R28: Salur
A29: =IF(D29="","",ROW()-1) -> 28 | B29: APBD Provinsi | C29: Induk | D29: Sipirok | E29: Saragodung | F29: Suka Bersama | G29: M Subuki | H29: 1203040801680003 | I29: 081361517671 | J29: 27 | K29: 10 | L29: 150 | M29: Pioneer 32 | N29: Mei | Q29: Ya | R29: Salur
A30: =IF(D30="","",ROW()-1) -> 29 | B30: APBD Provinsi | C30: Induk | D30: Sipirok | E30: Paranpadang | F30: Pukka Mandiri | G30: Marito Harahap | H30: 1203040610700002 | I30: 082214324196 | J30: 20 | K30: 10 | L30: 150 | M30: Pioneer 32 | N30: Mei | Q30: Ya | R30: Salur
A31: =IF(D31="","",ROW()-1) -> 30 | B31: APBD Provinsi | C31: Induk | D31: Sipirok | E31: Tolang | F31: Bersatu | G31: Sangkot Pane | H31: 1203042008800002 | I31: 82365465300 | J31: 25 | K31: 5 | L31: 75 | M31: Pioneer 32 | N31: Mei | Q31: Ya | R31: Salur
A32: =IF(D32="","",ROW()-1) -> 31 | B32: APBD Provinsi | C32: Induk | D32: Arse | E32: Nanggar Jati | F32: Dosniroha | G32: Zulkarna Marbun | H32: 1203142912760003 | I32: 081260735674 | J32: 20 | K32: 8 | L32: 120 | M32: Pioneer 32 | N32: Mei | Q32: Ya | R32: Salur
A33: =IF(D33="","",ROW()-1) -> 32 | B33: APBD Provinsi | C33: Induk | D33: Arse | E33: Sipogu | F33: Srikandi | G33: Sumarni Simatupang | H33: 1203144208820002 | I33: 082163424848 | J33: 17 | K33: 5 | L33: 75 | M33: Pioneer 32 | N33: Mei | Q33: Ya | R33: Salur
A34: =IF(D34="","",ROW()-1) -> 33 | B34: APBD Provinsi | C34: Induk | D34: Arse | E34: Natambang Roncitan | F34: Satahi | G34: Nurhasanah | H34: 1203144611600001 | I34: 081376929377 | J34: 36 | K34: 12 | L34: 180 | M34: Pioneer 32 | N34: Mei | Q34: Ya | R34: Salur
A35: =IF(D35="","",ROW()-1) -> 34 | B35: APBD Provinsi | C35: Induk | D35: Arse | E35: Aek Haminjon | F35: Sentosa Jaya | G35: Amsari | H35: 1203140608710002 | I35: 082276610133 | J35: 17 | K35: 8 | L35: 120 | M35: Pioneer 32 | N35: Mei | Q35: Ya | R35: Salur
A36: =IF(D36="","",ROW()-1) -> 35 | B36: APBD Provinsi | C36: Induk | D36: Arse | E36: Lancat | F36: Bariba | G36: Aminah Harahap | H36: 1203145509600001 | I36: 081376228930 | J36: 23 | K36: 8 | L36: 120 | M36: Pioneer 32 | N36: Mei | Q36: Ya | R36: Salur
A37: =IF(D37="","",ROW()-1) -> 36 | B37: APBD Provinsi | C37: Induk | D37: Arse | E37: Arse Nauli | F37: Satahi | G37: Tulus Pangidoan Silaban | H37: 1203140309820002 | I37: 085381320515 | J37: 20 | K37: 9 | L37: 135 | M37: Pioneer 32 | N37: Mei | Q37: Ya | R37: Salur
A38: =IF(D38="","",ROW()-1) -> 37 | B38: APBD Provinsi | C38: TKD | D38: Tano Tombangan Angkola | E38: Batu Horpak | F38: Saroha II | G38: Harapan Siregar | H38: 1203210602770002 | I38: 082177915437 | J38: 12 | K38: 15 | L38: 225 | M38: Pioneer 32 | N38: Juli | O38: 1°5'19'' | P38: 99°25'2'' | Q38: Ya | R38: Salur
A39: =IF(D39="","",ROW()-1) -> 38 | B39: APBD Provinsi | C39: TKD | D39: Tano Tombangan Angkola | E39: Ingul Jae | F39: Sepakat Baru | G39: Lastiar Pakpahan | H39: 1203215212810005 | I39: 081377066589 | J39: 20 | K39: 15 | L39: 225 | M39: Pioneer 32 | N39: Juli | O39: 1°2'40'' | P39: 99°26'42'' | Q39: Ya | R39: Salur
A40: =IF(D40="","",ROW()-1) -> 39 | B40: APBD Provinsi | C40: TKD | D40: Sayur Matinggi | E40: Lumban Huayan | F40: Aman Damai | G40: Sahaban Pane | H40: 1203210906820002 | I40: 085270356745 | J40: 35 | K40: 10 | L40: 150 | M40: Pioneer 32 | N40: Juli | O40: 1°7'10'' | P40: 99°25'14,''181,7m,284° | Q40: Ya | R40: Salur
A41: =IF(D41="","",ROW()-1) -> 40 | B41: APBD Provinsi | C41: TKD | D41: Sayur Matinggi | E41: Somanggal Parmonangan | F41: Serasi | G41: Sarma Sitohang | H41: 1203216006630002 | I41: 085768866281 | J41: 32 | K41: 10 | L41: 150 | M41: Pioneer 32 | N41: Juli | O41: 1°451" | P41: 99°25'49", 159,04,258° | Q41: Ya | R41: Salur
A42: =IF(D42="","",ROW()-1) -> 41 | B42: APBD Provinsi | C42: TKD | D42: Sayur Matinggi | E42: Janji Mauli Baringin | F42: Gemilang Tani | G42: Rinto | H42: '1203210107860273 | I42: '081262603092 | J42: 26 | K42: 10 | L42: 150 | M42: Pioneer 32 | N42: Juli | O42: 1°13'9' | P42: 99°22'46,"2024m | Q42: Ya | R42: Salur
A43: =IF(D43="","",ROW()-1) -> 42 | B43: APBD Provinsi | C43: TKD | D43: Sayur Matinggi | E43: Sialang | F43: Sinar Tani | G43: Indra Sugiarto | H43: 1203210907900004 | I43: 085297054861 | J43: 32 | K43: 10 | L43: 150 | M43: Pioneer 32 | N43: Juli | O43: 1.20922 | P43: 99,37115, 208,2 m,98° | Q43: Ya | R43: Salur
A44: =IF(D44="","",ROW()-1) -> 43 | B44: APBD Provinsi | C44: TKD | D44: Angkola Muara Tais | E44: Pargumbangan | F44: Satahi | G44: Hoirul Saleh | H44: 1203071106750002 | I44: 082214760344 | J44: 35 | K44: 5 | L44: 75 | M44: Pioneer 32 | N44: Juli | O44: 1°16'56" | P44: 99°21'13",214,9m,118° | Q44: Ya | R44: Salur
...

Sheet Rekap Kecamatan
A1: No | B1: Sumber Dana | C1: Kecamatan | D1: Poktan (Kelompok) | E1: Anggota (Orang) | F1: Luas (Ha) | G1: Benih (Kg)
A2: 1 | B2: APBD Kabupaten | C2: Aek Bilah | D2: =COUNTIFS('Data Penerima'!$B$2:$B$558,B2,'Data Penerima'!$D$2:$D$558,C2,'Data Penerima'!$F$2:$F$558,"?*") -> 0 | E2: =SUMIFS('Data Penerima'!$J$2:$J$558,'Data Penerima'!$B$2:$B$558,B2,'Data Penerima'!$D$2:$D$558,C2) -> 0 | F2: =SUMIFS('Data Penerima'!$K$2:$K$558,'Data Penerima'!$B$2:$B$558,B2,'Data Penerima'!$D$2:$D$558,C2) -> 0 | G2: =SUMIFS('Data Penerima'!$L$2:$L$558,'Data Penerima'!$B$2:$B$558,B2,'Data Penerima'!$D$2:$D$558,C2) -> 0
A3: 2 | B3: APBD Kabupaten | C3: Angkola Barat | D3: =COUNTIFS('Data Penerima'!$B$2:$B$558,B3,'Data Penerima'!$D$2:$D$558,C3,'Data Penerima'!$F$2:$F$558,"?*") -> 1 | E3: =SUMIFS('Data Penerima'!$J$2:$J$558,'Data Penerima'!$B$2:$B$558,B3,'Data Penerima'!$D$2:$D$558,C3) -> 30 | F3: =SUMIFS('Data Penerima'!$K$2:$K$558,'Data Penerima'!$B$2:$B$558,B3,'Data Penerima'!$D$2:$D$558,C3) -> 4 | G3: =SUMIFS('Data Penerima'!$L$2:$L$558,'Data Penerima'!$B$2:$B$558,B3,'Data Penerima'!$D$2:$D$558,C3) -> 60
A4: 3 | B4: APBD Kabupaten | C4: Angkola Muara Tais | D4: =COUNTIFS('Data Penerima'!$B$2:$B$558,B4,'Data Penerima'!$D$2:$D$558,C4,'Data Penerima'!$F$2:$F$558,"?*") -> 0 | E4: =SUMIFS('Data Penerima'!$J$2:$J$558,'Data Penerima'!$B$2:$B$558,B4,'Data Penerima'!$D$2:$D$558,C4) -> 0 | F4: =SUMIFS('Data Penerima'!$K$2:$K$558,'Data Penerima'!$B$2:$B$558,B4,'Data Penerima'!$D$2:$D$558,C4) -> 0 | G4: =SUMIFS('Data Penerima'!$L$2:$L$558,'Data Penerima'!$B$2:$B$558,B4,'Data Penerima'!$D$2:$D$558,C4) -> 0
A5: 4 | B5: APBD Kabupaten | C5: Angkola Sangkunur | D5: =COUNTIFS('Data Penerima'!$B$2:$B$558,B5,'Data Penerima'!$D$2:$D$558,C5,'Data Penerima'!$F$2:$F$558,"?*") -> 0 | E5: =SUMIFS('Data Penerima'!$J$2:$J$558,'Data Penerima'!$B$2:$B$558,B5,'Data Penerima'!$D$2:$D$558,C5) -> 0 | F5: =SUMIFS('Data Penerima'!$K$2:$K$558,'Data Penerima'!$B$2:$B$558,B5,'Data Penerima'!$D$2:$D$558,C5) -> 0 | G5: =SUMIFS('Data Penerima'!$L$2:$L$558,'Data Penerima'!$B$2:$B$558,B5,'Data Penerima'!$D$2:$D$558,C5) -> 0
A6: 5 | B6: APBD Kabupaten | C6: Angkola Selatan | D6: =COUNTIFS('Data Penerima'!$B$2:$B$558,B6,'Data Penerima'!$D$2:$D$558,C6,'Data Penerima'!$F$2:$F$558,"?*") -> 0 | E6: =SUMIFS('Data Penerima'!$J$2:$J$558,'Data Penerima'!$B$2:$B$558,B6,'Data Penerima'!$D$2:$D$558,C6) -> 0 | F6: =SUMIFS('Data Penerima'!$K$2:$K$558,'Data Penerima'!$B$2:$B$558,B6,'Data Penerima'!$D$2:$D$558,C6) -> 0 | G6: =SUMIFS('Data Penerima'!$L$2:$L$558,'Data Penerima'!$B$2:$B$558,B6,'Data Penerima'!$D$2:$D$558,C6) -> 0
A7: 6 | B7: APBD Kabupaten | C7: Angkola Timur | D7: =COUNTIFS('Data Penerima'!$B$2:$B$558,B7,'Data Penerima'!$D$2:$D$558,C7,'Data Penerima'!$F$2:$F$558,"?*") -> 0 | E7: =SUMIFS('Data Penerima'!$J$2:$J$558,'Data Penerima'!$B$2:$B$558,B7,'Data Penerima'!$D$2:$D$558,C7) -> 0 | F7: =SUMIFS('Data Penerima'!$K$2:$K$558,'Data Penerima'!$B$2:$B$558,B7,'Data Penerima'!$D$2:$D$558,C7) -> 0 | G7: =SUMIFS('Data Penerima'!$L$2:$L$558,'Data Penerima'!$B$2:$B$558,B7,'Data Penerima'!$D$2:$D$558,C7) -> 0
A8: 7 | B8: APBD Kabupaten | C8: Arse | D8: =COUNTIFS('Data Penerima'!$B$2:$B$558,B8,'Data Penerima'!$D$2:$D$558,C8,'Data Penerima'!$F$2:$F$558,"?*") -> 5 | E8: =SUMIFS('Data Penerima'!$J$2:$J$558,'Data Penerima'!$B$2:$B$558,B8,'Data Penerima'!$D$2:$D$558,C8) -> 93 | F8: =SUMIFS('Data Penerima'!$K$2:$K$558,'Data Penerima'!$B$2:$B$558,B8,'Data Penerima'!$D$2:$D$558,C8) -> 30 | G8: =SUMIFS('Data Penerima'!$L$2:$L$558,'Data Penerima'!$B$2:$B$558,B8,'Data Penerima'!$D$2:$D$558,C8) -> 450
A9: 8 | B9: APBD Kabupaten | C9: Batang Angkola | D9: =COUNTIFS('Data Penerima'!$B$2:$B$558,B9,'Data Penerima'!$D$2:$D$558,C9,'Data Penerima'!$F$2:$F$558,"?*") -> 2 | E9: =SUMIFS('Data Penerima'!$J$2:$J$558,'Data Penerima'!$B$2:$B$558,B9,'Data Penerima'!$D$2:$D$558,C9) -> 62 | F9: =SUMIFS('Data Penerima'!$K$2:$K$558,'Data Penerima'!$B$2:$B$558,B9,'Data Penerima'!$D$2:$D$558,C9) -> 9 | G9: =SUMIFS('Data Penerima'!$L$2:$L$558,'Data Penerima'!$B$2:$B$558,B9,'Data Penerima'!$D$2:$D$558,C9) -> 135
A10: 9 | B10: APBD Kabupaten | C10: Batang Toru | D10: =COUNTIFS('Data Penerima'!$B$2:$B$558,B10,'Data Penerima'!$D$2:$D$558,C10,'Data Penerima'!$F$2:$F$558,"?*") -> 0 | E10: =SUMIFS('Data Penerima'!$J$2:$J$558,'Data Penerima'!$B$2:$B$558,B10,'Data Penerima'!$D$2:$D$558,C10) -> 0 | F10: =SUMIFS('Data Penerima'!$K$2:$K$558,'Data Penerima'!$B$2:$B$558,B10,'Data Penerima'!$D$2:$D$558,C10) -> 0 | G10: =SUMIFS('Data Penerima'!$L$2:$L$558,'Data Penerima'!$B$2:$B$558,B10,'Data Penerima'!$D$2:$D$558,C10) -> 0
A11: 10 | B11: APBD Kabupaten | C11: Marancar | D11: =COUNTIFS('Data Penerima'!$B$2:$B$558,B11,'Data Penerima'!$D$2:$D$558,C11,'Data Penerima'!$F$2:$F$558,"?*") -> 1 | E11: =SUMIFS('Data Penerima'!$J$2:$J$558,'Data Penerima'!$B$2:$B$558,B11,'Data Penerima'!$D$2:$D$558,C11) -> 25 | F11: =SUMIFS('Data Penerima'!$K$2:$K$558,'Data Penerima'!$B$2:$B$558,B11,'Data Penerima'!$D$2:$D$558,C11) -> 4 | G11: =SUMIFS('Data Penerima'!$L$2:$L$558,'Data Penerima'!$B$2:$B$558,B11,'Data Penerima'!$D$2:$D$558,C11) -> 60
A12: 11 | B12: APBD Kabupaten | C12: Muara Batang Toru | D12: =COUNTIFS('Data Penerima'!$B$2:$B$558,B12,'Data Penerima'!$D$2:$D$558,C12,'Data Penerima'!$F$2:$F$558,"?*") -> 0 | E12: =SUMIFS('Data Penerima'!$J$2:$J$558,'Data Penerima'!$B$2:$B$558,B12,'Data Penerima'!$D$2:$D$558,C12) -> 0 | F12: =SUMIFS('Data Penerima'!$K$2:$K$558,'Data Penerima'!$B$2:$B$558,B12,'Data Penerima'!$D$2:$D$558,C12) -> 0 | G12: =SUMIFS('Data Penerima'!$L$2:$L$558,'Data Penerima'!$B$2:$B$558,B12,'Data Penerima'!$D$2:$D$558,C12) -> 0
A13: 12 | B13: APBD Kabupaten | C13: Saipar Dolok Hole | D13: =COUNTIFS('Data Penerima'!$B$2:$B$558,B13,'Data Penerima'!$D$2:$D$558,C13,'Data Penerima'!$F$2:$F$558,"?*") -> 2 | E13: =SUMIFS('Data Penerima'!$J$2:$J$558,'Data Penerima'!$B$2:$B$558,B13,'Data Penerima'!$D$2:$D$558,C13) -> 54 | F13: =SUMIFS('Data Penerima'!$K$2:$K$558,'Data Penerima'!$B$2:$B$558,B13,'Data Penerima'!$D$2:$D$558,C13) -> 15.333333 | G13: =SUMIFS('Data Penerima'!$L$2:$L$558,'Data Penerima'!$B$2:$B$558,B13,'Data Penerima'!$D$2:$D$558,C13) -> 230
... A61: 60 | B61: KUR BANK SUMUT | C61: Tano Tombangan Angkola | D61: =COUNTIFS('Data Penerima'!$B$2:$B$558,B61,'Data Penerima'!$D$2:$D$558,C61,'Data Penerima'!$F$2:$F$558,"?*") -> 0 | E61: =SUMIFS('Data Penerima'!$J$2:$J$558,'Data Penerima'!$B$2:$B$558,B61,'Data Penerima'!$D$2:$D$558,C61) -> 0 | F61: =SUMIFS('Data Penerima'!$K$2:$K$558,'Data Penerima'!$B$2:$B$558,B61,'Data Penerima'!$D$2:$D$558,C61) -> 0 | G61: =SUMIFS('Data Penerima'!$L$2:$L$558,'Data Penerima'!$B$2:$B$558,B61,'Data Penerima'!$D$2:$D$558,C61) -> 0
C62: TOTAL | D62: =SUM(D2:D61) -> 234 | E62: =SUM(E2:E61) -> 5380 | F62: =SUM(F2:F61) -> 2497.8267 | G62: =SUM(G2:G61) -> 37468.4

Sheet Rekap Sumber Dana
A1: No | B1: Sumber Dana | C1: Poktan (Kelompok) | D1: Anggota (Orang) | E1: Luas (Ha) | F1: Benih (Kg) | G1: Tautan Berkas (Google Drive)
A2: 1 | B2: APBD Kabupaten | C2: =COUNTIFS('Data Penerima'!$B$2:$B$558,B2,'Data Penerima'!$F$2:$F$558,"?*") -> 22 | D2: =SUMIF('Data Penerima'!$B$2:$B$558,B2,'Data Penerima'!$J$2:$J$558) -> 515 | E2: =SUMIF('Data Penerima'!$B$2:$B$558,B2,'Data Penerima'!$K$2:$K$558) -> 111.26667 | F2: =SUMIF('Data Penerima'!$B$2:$B$558,B2,'Data Penerima'!$L$2:$L$558) -> 1670 | G2: https://drive.google.com/drive/folders/1zkWlxYJZ8rgcbQeMsYmVeSfODSvVGuQw?usp=drive_link
A3: 2 | B3: APBD Provinsi | C3: =COUNTIFS('Data Penerima'!$B$2:$B$558,B3,'Data Penerima'!$F$2:$F$558,"?*") -> 34 | D3: =SUMIF('Data Penerima'!$B$2:$B$558,B3,'Data Penerima'!$J$2:$J$558) -> 800 | E3: =SUMIF('Data Penerima'!$B$2:$B$558,B3,'Data Penerima'!$K$2:$K$558) -> 266 | F3: =SUMIF('Data Penerima'!$B$2:$B$558,B3,'Data Penerima'!$L$2:$L$558) -> 3990 | G3: https://drive.google.com/drive/folders/1s-OqaY0tsHwxdUSlofxQ8Uk-tNaYYwlJ?usp=drive_link
A4: 3 | B4: APBN | C4: =COUNTIFS('Data Penerima'!$B$2:$B$558,B4,'Data Penerima'!$F$2:$F$558,"?*") -> 178 | D4: =SUMIF('Data Penerima'!$B$2:$B$558,B4,'Data Penerima'!$J$2:$J$558) -> 3974 | E4: =SUMIF('Data Penerima'!$B$2:$B$558,B4,'Data Penerima'!$K$2:$K$558) -> 1960 | F4: =SUMIF('Data Penerima'!$B$2:$B$558,B4,'Data Penerima'!$L$2:$L$558) -> 29400 | G4: https://drive.google.com/drive/folders/1rX9LoeGsLej7Tcv5J1pYOot0KZ57YT1x?usp=drive_link
A5: 4 | B5: KUR BANK SUMUT | C5: =COUNTIFS('Data Penerima'!$B$2:$B$558,B5,'Data Penerima'!$F$2:$F$558,"?*") -> 0 | D5: =SUMIF('Data Penerima'!$B$2:$B$558,B5,'Data Penerima'!$J$2:$J$558) -> 91 | E5: =SUMIF('Data Penerima'!$B$2:$B$558,B5,'Data Penerima'!$K$2:$K$558) -> 160.56 | F5: =SUMIF('Data Penerima'!$B$2:$B$558,B5,'Data Penerima'!$L$2:$L$558) -> 2408.4 | G5: https://drive.google.com/drive/folders/1ZUMhN6UtkgnQSuCunWYF8egT5skmjzTP?usp=drive_link
B6: TOTAL | C6: =SUM(C2:C5) -> 234 | D6: =SUM(D2:D5) -> 5380 | E6: =SUM(E2:E5) -> 2497.8267 | F6: =SUM(F2:F5) -> 37468.4

Sheet Tanam dan Panen
A1: Sasaran tanam oktober 2025-september 2026
A3: No | B3: Kecamatan | C3: 2025 | F3: 2026 | O3: MT APRIL sd SEPT
C4: OKT | D4: NOP | E4: DES | F4: JAN | G4: FEB | H4: MAR | I4: APRIL | J4: MEI | K4: JUNI | L4: JULI | M4: AGUST | N4: SEPT
A5: 1 | B5: BATANG ANGKOLA | C5: 7.0633167 | D5: 14.126633 | E5: 7.0633167 | F5: 7.0633167 | G5: 7.0633167 | H5: 7.0633167 | I5: 7.0633167 | J5: 5.6506533 | K5: 7.0633167 | L5: 32.491257 | M5: 7.0633167 | N5: 14.126633 | O5: =SUM(C5:N5) -> 122.90171
A6: 2 | B6: SAYUR MATINGGI | C6: 0 | D6: 18.364623 | E6: 21.18995 | F6: 5.6506533 | G6: 2.8253267 | H6: 0 | I6: 4.23799 | J6: 0 | K6: 0 | L6: 7.0633167 | M6: 2.8253267 | N6: 7.0633167 | O6: =SUM(C6:N6) -> 69.220503
A7: 3 | B7: TANO TOMBANGAN ANGKOLA | C7: 218.96282 | D7: 275.46935 | E7: 125.72704 | F7: 122.90171 | G7: 240.15277 | H7: 226.02613 | I7: 91.823117 | J7: 103.12442 | K7: 0 | L7: 91.823117 | M7: 125.72704 | N7: 230.26412 | O7: =SUM(C7:N7) -> 1852.0016
A8: 4 | B8: ANGKOLA MUARA TAIS | C8: 2.8253267 | D8: 2.8253267 | E8: 2.8253267 | F8: 2.8253267 | G8: 2.8253267 | H8: 2.8253267 | I8: 2.8253267 | J8: 2.8253267 | K8: 2.8253267 | L8: 2.8253267 | M8: 2.8253267 | N8: 2.8253267 | O8: =SUM(C8:N8) -> 33.90392
A9: 5 | B9: ANGKOLA TIMUR | C9: 1.4126633 | D9: 1.4126633 | E9: 1.4126633 | F9: 1.4126633 | G9: 2.8253267 | H9: 1.4126633 | I9: 0 | J9: 1.4126633 | K9: 1.4126633 | L9: 2.8253267 | M9: 2.8253267 | N9: 1.4126633 | O9: =SUM(C9:N9) -> 19.777287
A10: 6 | B10: ANGKOLA SELATAN | C10: 0 | D10: 50.85588 | E10: 28.253267 | F10: 53.681207 | G10: 48.030553 | H10: 1.4126633 | I10: 2.8253267 | J10: 21.18995 | K10: 50.85588 | L10: 0 | M10: 14.126633 | N10: 35.316583 | O10: =SUM(C10:N10) -> 306.54794
A11: 7 | B11: ANGKOLA BARAT | C11: 1.4126633 | D11: 1.4126633 | E11: 1.4126633 | F11: 1.4126633 | G11: 1.4126633 | H11: 1.4126633 | I11: 1.4126633 | J11: 1.4126633 | K11: 0 | L11: 1.4126633 | M11: 1.4126633 | N11: 1.4126633 | O11: =SUM(C11:N11) -> 15.539297
A12: 8 | B12: ANGKOLA SANGKUNUR | C12: 141.26633 | D12: 70.633167 | E12: 22.602613 | F12: 25.42794 | G12: 52.268543 | H12: 39.554573 | I12: 18.364623 | J12: 36.729247 | K12: 14.126633 | L12: 14.126633 | M12: 14.126633 | N12: 70.633167 | O12: =SUM(C12:N12) -> 519.86011
A13: 9 | B13: BATANG TORU | C13: 14.126633 | D13: 14.126633 | E13: 14.126633 | F13: 7.0633167 | G13: 56.506533 | H13: 35.316583 | I13: 0 | J13: 12.71397 | K13: 2.8253267 | L13: 26.840603 | M13: 28.253267 | N13: 21.18995 | O13: =SUM(C13:N13) -> 233.08945
A14: 10 | B14: MARANCAR | C14: 7.0633167 | D14: 14.126633 | E14: 8.47598 | F14: 14.126633 | G14: 14.126633 | H14: 7.0633167 | I14: 7.0633167 | J14: 9.8886433 | K14: 9.8886433 | L14: 7.0633167 | M14: 7.0633167 | N14: 7.7696483 | O14: =SUM(C14:N14) -> 113.7194
A15: 11 | B15: MUARA BATANG TORU | C15: 0 | D15: 0 | E15: 0 | F15: 0 | G15: 0.70633167 | H15: 7.0633167 | I15: 1.4126633 | J15: 15.539297 | K15: 0 | L15: 11.301307 | M15: 0 | N15: 31.078593 | O15: =SUM(C15:N15) -> 67.101508
A16: 12 | B16: SIPIROK | C16: 2.8253267 | D16: 6.356985 | E16: 5.6506533 | F16: 13.420302 | G16: 2.8253267 | H16: 2.8253267 | I16: 18.364623 | J16: 0.70633167 | K16: 11.145914 | L16: 21.543116 | M16: 8.1510674 | N16: 21.18995 | O16: =SUM(C16:N16) -> 115.00492
... A19: 15 | B19: AEK BILAH | C19: 28.253267 | D19: 28.253267 | E19: 38.14191 | F19: 0 | G19: 0 | H19: 2.8253267 | I19: 0 | J19: 7.0633167 | K19: 0 | L19: 0 | M19: 2.8253267 | N19: 4.23799 | O19: =SUM(C19:N19) -> 111.6004
B20: TOTAL | C20: =SUM(C5:C19) -> 615.92121 | D20: =SUM(D5:D19) -> 729.64061 | E20: =SUM(E5:E19) -> 365.8798 | F20: =SUM(F5:F19) -> 314.31759 | G20: =SUM(G5:G19) -> 466.88523 | H20: =SUM(H5:H19) -> 396.9584 | I20: =SUM(I5:I19) -> 199.18553 | J20: =SUM(J5:J19) -> 263.46171 | ... O20: =SUM(O5:O19) -> 4461.77
A22: Realisasi Tanam Jagung Oktober 2025 - September 2026
A23: No | B23: Kecamatan | C23: 2025 | F23: 2026 | I23: 2026 | O23: MT APRIL sd SEPT
C24: OKT | D24: NOP | E24: DES | F24: JAN | G24: FEB | H24: MAR | I24: APRIL | J24: MEI | K24: JUNI | L24: JULI | M24: AGUST | N24: SEPT
A25: 1 | B25: BATANG ANGKOLA | C25: 45 | D25: 55 | E25: 80 | F25: 24 | G25: 25 | H25: 13 | I25: 0 | J25: 11.5 | K25: 20 | L25: 13 | M25: 6 | N25: 3 | O25: =SUM(C25:N25) -> 295.5
A26: 2 | B26: SAYUR MATINGGI | C26: 35 | D26: 63 | E26: 40 | F26: 30 | G26: 58 | H26: 25 | I26: 45 | J26: 18 | K26: 1 | L26: 6 | M26: 2 | N26: 24 | O26: =SUM(C26:N26) -> 347
A27: 3 | B27: TANO TOMBANGAN ANGKOLA | C27: 102 | D27: 97 | E27: 102 | F27: 95 | G27: 99 | H27: 192 | I27: 40 | J27: 32 | K27: 25 | L27: 81 | M27: 72 | N27: 42 | O27: =SUM(C27:N27) -> 979
A28: 4 | B28: ANGKOLA MUARA TAIS | C28: 26 | D28: 14 | E28: 24 | F28: 58 | G28: 2 | H28: 2 | I28: 3 | J28: 3 | K28: 2 | L28: 3 | M28: 3 | N28: 13 | O28: =SUM(C28:N28) -> 153
A29: 5 | B29: ANGKOLA TIMUR | C29: 32 | D29: 31 | E29: 20 | F29: 40 | G29: 10 | H29: 1 | I29: 3 | J29: 0 | K29: 0 | L29: 1 | M29: 3 | N29: 6 | O29: =SUM(C29:N29) -> 147
A30: 6 | B30: ANGKOLA SELATAN | C30: 95 | D30: 35 | E30: 24 | F30: 38 | G30: 1 | H30: 2 | I30: 0 | J30: 2 | K30: 2 | L30: 4 | M30: 2 | N30: 16 | O30: =SUM(C30:N30) -> 221
A31: 7 | B31: ANGKOLA BARAT | C31: 10 | D31: 20 | E31: 10 | F31: 1 | G31: 6.5 | H31: 11.45 | I31: 6.65 | J31: 4.5 | K31: 2 | L31: 4 | M31: 4 | N31: 10 | O31: =SUM(C31:N31) -> 90.1
A32: 8 | B32: ANGKOLA SANGKUNUR | C32: 15 | D32: 40 | E32: 10 | F32: 0 | G32: 4 | H32: 0 | I32: 10 | J32: 8 | K32: 10 | L32: 4 | M32: 0 | N32: 3 | O32: =SUM(C32:N32) -> 104
A33: 9 | B33: BATANG TORU | C33: 44 | D33: 49 | E33: 0 | F33: 0 | G33: 20 | H33: 0 | I33: 24 | J33: 5 | K33: 17 | L33: 5 | M33: 5 | N33: 5 | O33: =SUM(C33:N33) -> 174
A34: 10 | B34: MARANCAR | C34: 25 | D34: 20 | E34: 10 | F34: 4 | G34: 5 | H34: 1 | I34: 4 | J34: 4 | K34: 5 | L34: 6 | M34: 3 | N34: 5 | O34: =SUM(C34:N34) -> 92
A35: 11 | B35: MUARA BATANG TORU | C35: 65 | D35: 40 | E35: 0 | F35: 0 | G35: 6.5 | H35: 5.75 | I35: 0 | J35: 0 | K35: 0 | L35: 7.25 | M35: 0 | N35: 0 | O35: =SUM(C35:N35) -> 124.5
A36: 12 | B36: SIPIROK | C36: 79 | D36: 48 | E36: 55 | F36: 20.25 | G36: 91.58 | H36: 74 | I36: 59 | J36: 30 | K36: 28.7 | L36: 19.5 | M36: 50.26 | N36: 35 | O36: =SUM(C36:N36) -> 590.29
... A39: 15 | B39: AEK BILAH | C39: 100 | D39: 132 | E39: 95 | F39: 0 | G39: 0 | H39: 2 | I39: 55 | J39: 0 | K39: 0 | L39: 0 | M39: 0 | N39: 8.5 | O39: =SUM(C39:N39) -> 392.5
B40: TOTAL | C40: =SUM(C25:C39) -> 933 | D40: =SUM(D25:D39) -> 877 | E40: =SUM(E25:E39) -> 650 | F40: =SUM(F25:F39) -> 324.25 | G40: =SUM(G25:G39) -> 453.58 | H40: =SUM(H25:H39) -> 344.7 | I40: =SUM(I25:I39) -> 324.15 | J40: =SUM(J25:J39) -> 162 | ... O40: =SUM(O25:O39) -> 4795.89
M41: Selisih target-realisasi | O41: =O40-O20 -> 334.12 | P41: =O40/O20 -> 1.0748851
A43: Luas Puso (Gagal Panen)
A44: No | B44: Kecamatan | C44: 2025 | F44: 2026 | I44: 2026 | O44: MT APRIL sd SEPT
C45: OKT | D45: NOP | E45: DES | F45: JAN | G45: FEB | H45: MAR | I45: APRIL | J45: MEI | K45: JUNI | L45: JULI | M45: AGUST | N45: SEPT
A46: 1 | B46: BATANG ANGKOLA | C46: 0 | D46: 0 | E46: 25 | F46: 13 | G46: 17 | H46: 50 | I46: 0 | J46: 0 | K46: 0 | L46: 0 | M46: 0 | N46: 0 | O46: =SUM(C46:N46) -> 105
A47: 2 | B47: SAYUR MATINGGI | C47: 0 | D47: 3 | E47: 8 | F47: 25 | G47: 42 | H47: 23 | I47: 0 | J47: 0 | K47: 0 | L47: 0 | M47: 0 | N47: 0 | O47: =SUM(C47:N47) -> 101
...

Sheet Panen dan Produksi
A1: LUAS PANEN DAN PRODUKSI JAGUNG PER TRIWULAN
A2: KABUPATEN TAPANULI SELATAN TAHUN 2026
A3: Produktivitas : 60 kw/Ha
C4: TRIWULAN I | K4: TRIWULAN II | S4: TRIWULAN III | AA4: TRIWULAN IV | AI4: TOTAL SETAHUN
A5: No | B5: Nama Kecamatan | C5: LUAS PANEN (HA) | G5: PRODUKSI (TON) | K5: LUAS PANEN (HA) | O5: PRODUKSI (TON) | S5: LUAS PANEN (HA) | W5: PRODUKSI (TON) | AA5: LUAS PANEN (HA) | AE5: PRODUKSI (TON) | AI5: LUAS PANEN | AJ5: PRODUKSI
C6: Jan | D6: Feb | E6: Mar | F6: TOTAL | G6: Jan | H6: Feb | I6: Mar | J6: TOTAL | K6: Apr | L6: Mei | M6: Jun | N6: TOTAL | O6: Apr | P6: Mei | Q6: Jun | R6: TOTAL | S6: Jul | T6: Agust | U6: Sept | V6: TOTAL | W6: Jul | X6: Agust | Y6: Sept | Z6: TOTAL | AA6: Okt | AB6: Nov | AC6: Des | AD6: TOTAL | AE6: Okt | AF6: Nov | AG6: Des | AH6: TOTAL
A7: 1 | B7: BATANG ANGKOLA | C7: 33 | D7: 39 | E7: 0 | F7: =SUM(C7:E7) -> 72 | G7: =C7*6 -> 198 | H7: =D7*6 -> 234 | I7: =E7*6 -> 0 | J7: =SUM(G7:I7) -> 432 | K7: 13 | L7: 30 | M7: 5 | N7: =SUM(K7:M7) -> 48 | O7: =K7*6 -> 78 | P7: =L7*6 -> 180 | Q7: =M7*6 -> 30 | R7: =SUM(O7:Q7) -> 288 | S7: 13 | T7: 0 | U7: 20 | V7: =SUM(S7:U7) -> 33 | W7: =S7*6 -> 78 | X7: =T7*6 -> 0 | Y7: =U7*6 -> 120 | Z7: =SUM(W7:Y7) -> 198 | AD7: =SUM(AA7:AC7) -> 0 | AE7: =AA7*8 -> 0 | AF7: =AB7*8 -> 0 | AG7: =AC7*8 -> 0 | AH7: =SUM(AE7:AG7) -> 0 | AI7: =SUM(F7,N7,V7,AD7) -> 153 | AJ7: =SUM(J7,R7,Z7,AH7) -> 918
A8: 2 | B8: SAYUR MATINGGI | C8: 11 | D8: 24 | E8: 0 | F8: =SUM(C8:E8) -> 35 | G8: =C8*6 -> 66 | H8: =D8*6 -> 144 | I8: =E8*6 -> 0 | J8: =SUM(G8:I8) -> 210 | K8: 15 | L8: 6 | M8: 2 | N8: =SUM(K8:M8) -> 23 | O8: =K8*6 -> 90 | P8: =L8*6 -> 36 | Q8: =M8*6 -> 12 | R8: =SUM(O8:Q8) -> 138 | S8: 25 | T8: 8 | U8: 3 | V8: =SUM(S8:U8) -> 36 | W8: =S8*6 -> 150 | X8: =T8*6 -> 48 | Y8: =U8*6 -> 18 | Z8: =SUM(W8:Y8) -> 216 | AD8: =SUM(AA8:AC8) -> 0 | AE8: =AA8*8 -> 0 | AF8: =AB8*8 -> 0 | AG8: =AC8*8 -> 0 | AH8: =SUM(AE8:AG8) -> 0 | AI8: =SUM(F8,N8,V8,AD8) -> 94 | AJ8: =SUM(J8,R8,Z8,AH8) -> 564
A9: 3 | B9: TANO TOMBANGAN ANGKOLA | C9: 172 | D9: 92 | E9: 96 | F9: =SUM(C9:E9) -> 360 | G9: =C9*6 -> 1032 | H9: =D9*6 -> 552 | I9: =E9*6 -> 576 | J9: =SUM(G9:I9) -> 2160 | K9: 95 | L9: 99 | M9: 70 | N9: =SUM(K9:M9) -> 264 | O9: =K9*6 -> 570 | P9: =L9*6 -> 594 | Q9: =M9*6 -> 420 | R9: =SUM(O9:Q9) -> 1584 | S9: 20 | T9: 40 | U9: 32 | V9: =SUM(S9:U9) -> 92 | W9: =S9*6 -> 120 | X9: =T9*6 -> 240 | Y9: =U9*6 -> 192 | Z9: =SUM(W9:Y9) -> 552 | AD9: =SUM(AA9:AC9) -> 0 | AE9: =AA9*8 -> 0 | AF9: =AB9*8 -> 0 | AG9: =AC9*8 -> 0 | AH9: =SUM(AE9:AG9) -> 0 | AI9: =SUM(F9,N9,V9,AD9) -> 716 | AJ9: =SUM(J9,R9,Z9,AH9) -> 4296
A10: 4 | B10: ANGKOLA MUARA TAIS | C10: 45 | D10: 33 | E10: 52 | F10: =SUM(C10:E10) -> 130 | G10: =C10*6 -> 270 | H10: =D10*6 -> 198 | I10: =E10*6 -> 312 | J10: =SUM(G10:I10) -> 780 | K10: 2 | L10: 2 | M10: 2 | N10: =SUM(K10:M10) -> 6 | O10: =K10*6 -> 12 | P10: =L10*6 -> 12 | Q10: =M10*6 -> 12 | R10: =SUM(O10:Q10) -> 36 | S10: 2 | T10: 2 | U10: 2 | V10: =SUM(S10:U10) -> 6 | W10: =S10*6 -> 12 | X10: =T10*6 -> 12 | Y10: =U10*6 -> 12 | Z10: =SUM(W10:Y10) -> 36 | AD10: =SUM(AA10:AC10) -> 0 | AE10: =AA10*8 -> 0 | AF10: =AB10*8 -> 0 | AG10: =AC10*8 -> 0 | AH10: =SUM(AE10:AG10) -> 0 | AI10: =SUM(F10,N10,V10,AD10) -> 142 | AJ10: =SUM(J10,R10,Z10,AH10) -> 852
A11: 5 | B11: ANGKOLA TIMUR | C11: 30 | D11: 36 | E11: 14 | F11: =SUM(C11:E11) -> 80 | G11: =C11*6 -> 180 | H11: =D11*6 -> 216 | I11: =E11*6 -> 84 | J11: =SUM(G11:I11) -> 480 | K11: 1 | L11: 0 | M11: 35 | N11: =SUM(K11:M11) -> 36 | O11: =K11*6 -> 6 | P11: =L11*6 -> 0 | Q11: =M11*6 -> 210 | R11: =SUM(O11:Q11) -> 216 | S11: 0 | T11: 7 | U11: 3 | V11: =SUM(S11:U11) -> 10 | W11: =S11*6 -> 0 | X11: =T11*6 -> 42 | Y11: =U11*6 -> 18 | Z11: =SUM(W11:Y11) -> 60 | AD11: =SUM(AA11:AC11) -> 0 | AE11: =AA11*8 -> 0 | AF11: =AB11*8 -> 0 | AG11: =AC11*8 -> 0 | AH11: =SUM(AE11:AG11) -> 0 | AI11: =SUM(F11,N11,V11,AD11) -> 126 | AJ11: =SUM(J11,R11,Z11,AH11) -> 756
A12: 6 | B12: ANGKOLA SELATAN | C12: 71 | D12: 21 | E12: 0 | F12: =SUM(C12:E12) -> 92 | G12: =C12*6 -> 426 | H12: =D12*6 -> 126 | I12: =E12*6 -> 0 | J12: =SUM(G12:I12) -> 552 | K12: 50 | L12: 42 | M12: 1 | N12: =SUM(K12:M12) -> 93 | O12: =K12*6 -> 300 | P12: =L12*6 -> 252 | Q12: =M12*6 -> 6 | R12: =SUM(O12:Q12) -> 558 | S12: 2 | T12: 3 | U12: 32 | V12: =SUM(S12:U12) -> 37 | W12: =S12*6 -> 12 | X12: =T12*6 -> 18 | Y12: =U12*6 -> 192 | Z12: =SUM(W12:Y12) -> 222 | AD12: =SUM(AA12:AC12) -> 0 | AE12: =AA12*8 -> 0 | AF12: =AB12*8 -> 0 | AG12: =AC12*8 -> 0 | AH12: =SUM(AE12:AG12) -> 0 | AI12: =SUM(F12,N12,V12,AD12) -> 222 | AJ12: =SUM(J12,R12,Z12,AH12) -> 1332
A13: 7 | B13: ANGKOLA BARAT | C13: 11 | D13: 11 | E13: 1 | F13: =SUM(C13:E13) -> 23 | G13: =C13*6 -> 66 | H13: =D13*6 -> 66 | I13: =E13*6 -> 6 | J13: =SUM(G13:I13) -> 138 | K13: 1 | L13: 3 | M13: 7 | N13: =SUM(K13:M13) -> 11 | O13: =K13*6 -> 6 | P13: =L13*6 -> 18 | Q13: =M13*6 -> 42 | R13: =SUM(O13:Q13) -> 66 | S13: 6 | T13: 6 | U13: 5 | V13: =SUM(S13:U13) -> 17 | W13: =S13*6 -> 36 | X13: =T13*6 -> 36 | Y13: =U13*6 -> 30 | Z13: =SUM(W13:Y13) -> 102 | AD13: =SUM(AA13:AC13) -> 0 | AE13: =AA13*8 -> 0 | AF13: =AB13*8 -> 0 | AG13: =AC13*8 -> 0 | AH13: =SUM(AE13:AG13) -> 0 | AI13: =SUM(F13,N13,V13,AD13) -> 51 | AJ13: =SUM(J13,R13,Z13,AH13) -> 306
A14: 8 | B14: ANGKOLA SANGKUNUR | C14: 13 | D14: 24 | E14: 0 | F14: =SUM(C14:E14) -> 37 | G14: =C14*6 -> 78 | H14: =D14*6 -> 144 | I14: =E14*6 -> 0 | J14: =SUM(G14:I14) -> 222 | K14: 18 | L14: 6 | M14: 4 | N14: =SUM(K14:M14) -> 28 | O14: =K14*6 -> 108 | P14: =L14*6 -> 36 | Q14: =M14*6 -> 24 | R14: =SUM(O14:Q14) -> 168 | S14: 8 | T14: 0 | U14: 10 | V14: =SUM(S14:U14) -> 18 | W14: =S14*6 -> 48 | X14: =T14*6 -> 0 | Y14: =U14*6 -> 60 | Z14: =SUM(W14:Y14) -> 108 | AD14: =SUM(AA14:AC14) -> 0 | AE14: =AA14*8 -> 0 | AF14: =AB14*8 -> 0 | AG14: =AC14*8 -> 0 | AH14: =SUM(AE14:AG14) -> 0 | AI14: =SUM(F14,N14,V14,AD14) -> 83 | AJ14: =SUM(J14,R14,Z14,AH14) -> 498
A15: 9 | B15: BATANG TORU | C15: 9 | D15: 24 | E15: 0 | F15: =SUM(C15:E15) -> 33 | G15: =C15*6 -> 54 | H15: =D15*6 -> 144 | I15: =E15*6 -> 0 | J15: =SUM(G15:I15) -> 198 | K15: 0 | L15: 0 | M15: 7 | N15: =SUM(K15:M15) -> 7 | O15: =K15*6 -> 0 | P15: =L15*6 -> 0 | Q15: =M15*6 -> 42 | R15: =SUM(O15:Q15) -> 42 | S15: 13 | T15: 13 | U15: 15 | V15: =SUM(S15:U15) -> 41 | W15: =S15*6 -> 78 | X15: =T15*6 -> 78 | Y15: =U15*6 -> 90 | Z15: =SUM(W15:Y15) -> 246 | AD15: =SUM(AA15:AC15) -> 0 | AE15: =AA15*8 -> 0 | AF15: =AB15*8 -> 0 | AG15: =AC15*8 -> 0 | AH15: =SUM(AE15:AG15) -> 0 | AI15: =SUM(F15,N15,V15,AD15) -> 81 | AJ15: =SUM(J15,R15,Z15,AH15) -> 486
A16: 10 | B16: MARANCAR | C16: 20 | D16: 18 | E16: 5 | F16: =SUM(C16:E16) -> 43 | G16: =C16*6 -> 120 | H16: =D16*6 -> 108 | I16: =E16*6 -> 30 | J16: =SUM(G16:I16) -> 258 | K16: 10 | L16: 6 | M16: 5 | N16: =SUM(K16:M16) -> 21 | O16: =K16*6 -> 60 | P16: =L16*6 -> 36 | Q16: =M16*6 -> 30 | R16: =SUM(O16:Q16) -> 126 | S16: 4 | T16: 6 | U16: 5 | V16: =SUM(S16:U16) -> 15 | W16: =S16*6 -> 24 | X16: =T16*6 -> 36 | Y16: =U16*6 -> 30 | Z16: =SUM(W16:Y16) -> 90 | AD16: =SUM(AA16:AC16) -> 0 | AE16: =AA16*8 -> 0 | AF16: =AB16*8 -> 0 | AG16: =AC16*8 -> 0 | AH16: =SUM(AE16:AG16) -> 0 | AI16: =SUM(F16,N16,V16,AD16) -> 79 | AJ16: =SUM(J16,R16,Z16,AH16) -> 474
A17: 11 | B17: MUARA BATANG TORU | C17: 4.5 | D17: 0 | E17: 0 | F17: =SUM(C17:E17) -> 4.5 | G17: =C17*6 -> 27 | H17: =D17*6 -> 0 | I17: =E17*6 -> 0 | J17: =SUM(G17:I17) -> 27 | K17: 0 | L17: 6.5 | M17: 5.75 | N17: =SUM(K17:M17) -> 12.25 | O17: =K17*6 -> 0 | P17: =L17*6 -> 39 | Q17: =M17*6 -> 34.5 | R17: =SUM(O17:Q17) -> 73.5 | S17: 0 | T17: 0 | U17: 0 | V17: =SUM(S17:U17) -> 0 | W17: =S17*6 -> 0 | X17: =T17*6 -> 0 | Y17: =U17*6 -> 0 | Z17: =SUM(W17:Y17) -> 0 | AD17: =SUM(AA17:AC17) -> 0 | AE17: =AA17*8 -> 0 | AF17: =AB17*8 -> 0 | AG17: =AC17*8 -> 0 | AH17: =SUM(AE17:AG17) -> 0 | AI17: =SUM(F17,N17,V17,AD17) -> 16.75 | AJ17: =SUM(J17,R17,Z17,AH17) -> 100.5
A18: 12 | B18: SIPIROK | C18: 34 | D18: 19 | E18: 0.14 | F18: =SUM(C18:E18) -> 53.14 | G18: =C18*6 -> 204 | H18: =D18*6 -> 114 | I18: =E18*6 -> 0.84 | J18: =SUM(G18:I18) -> 318.84 | K18: 44.79 | L18: 67.04 | M18: 67.4 | N18: =SUM(K18:M18) -> 179.23 | O18: =K18*6 -> 268.74 | P18: =L18*6 -> 402.24 | Q18: =M18*6 -> 404.4 | R18: =SUM(O18:Q18) -> 1075.38 | S18: 74 | T18: 32.5 | U18: 33.7 | V18: =SUM(S18:U18) -> 140.2 | W18: =S18*6 -> 444 | X18: =T18*6 -> 195 | Y18: =U18*6 -> 202.2 | Z18: =SUM(W18:Y18) -> 841.2 | AD18: =SUM(AA18:AC18) -> 0 | AE18: =AA18*8 -> 0 | AF18: =AB18*8 -> 0 | AG18: =AC18*8 -> 0 | AH18: =SUM(AE18:AG18) -> 0 | AI18: =SUM(F18,N18,V18,AD18) -> 372.57 | AJ18: =SUM(J18,R18,Z18,AH18) -> 2235.42
... A21: 15 | B21: AEK BILAH | C21: 100 | D21: 132 | E21: 0 | F21: =SUM(C21:E21) -> 232 | G21: =C21*6 -> 600 | H21: =D21*6 -> 792 | I21: =E21*6 -> 0 | J21: =SUM(G21:I21) -> 1392 | K21: 0 | L21: 4 | M21: 0 | N21: =SUM(K21:M21) -> 4 | O21: =K21*6 -> 0 | P21: =L21*6 -> 24 | Q21: =M21*6 -> 0 | R21: =SUM(O21:Q21) -> 24 | S21: 95 | T21: 0 | U21: 0 | V21: =SUM(S21:U21) -> 95 | W21: =S21*6 -> 570 | X21: =T21*6 -> 0 | Y21: =U21*6 -> 0 | Z21: =SUM(W21:Y21) -> 570 | AD21: =SUM(AA21:AC21) -> 0 | AE21: =AA21*8 -> 0 | AF21: =AB21*8 -> 0 | AG21: =AC21*8 -> 0 | AH21: =SUM(AE21:AG21) -> 0 | AI21: =SUM(F21,N21,V21,AD21) -> 331 | AJ21: =SUM(J21,R21,Z21,AH21) -> 1986
A22: Total | C22: =SUM(C7:C21) -> 723.5 | D22: =SUM(D7:D21) -> 631 | E22: =SUM(E7:E21) -> 183.14 | F22: =SUM(F7:F21) -> 1537.64 | G22: =SUM(G7:G21) -> 4341 | H22: =SUM(H7:H21) -> 3786 | I22: =SUM(I7:I21) -> 1098.84 | J22: =SUM(J7:J21) -> 9225.84 | ... AJ22: =SUM(AJ7:AJ21) -> 18649.92

Sheet Petunjuk
A1: PETUNJUK PENGISIAN — BANTUAN JAGUNG 2026
A2: 1. Input seluruh data pada sheet Data Penerima; kolom Sumber Dana merupakan tambahan dari contoh.
A3: 2. Satu baris = satu penerima/lokasi/alokasi bantuan; jangan memasukkan rencana sebagai realisasi.
A4: 3. Rekap Kecamatan dan Rekap Sumber Dana menghitung otomatis dari Data Penerima.
A5: 4. Angka Poktan = jumlah baris kelompok penerima; bukan jumlah kelompok unik lintas sumber dana.
A6: 5. Kolom luas dan benih dijumlahkan per alokasi; bila lokasi sama mendapatkan bantuan ganda, periksa potensi duplikasi.
A7: 6. Format rekap ini khusus benih jagung. Bantuan alsintan, pupuk, dll membutuhkan satuan masing-masing.
